Workbook

Sheet Summary
B2: XYZ
C6: Evaluation of the last 3 sprints
C26: M2 TEAM RESULTS / LAST 20 SPRINTS
C63: TEAM COMPARISON

Sheet Results
A1: Sprint 22 | K1: Scales
B2: Completed scope | C2: Scope vs Team (h) | D2: Fokus rate | E2: Capacity | F2: Timeout of the task | G2: Team's NPS | H2: Score | K2: Completed scope | L2: Scope vs Team (h) | M2: Fokus rate | N2: Capacity | O2: Timeout of the task | P2: Team's NPS
A3: Scale | B3: =$K$3 -> 1.2 | C3: =$L$3 -> 1.2 | D3: =$M$3 -> 1.8 | E3: =$N$3 -> 1 | F3: =$O$3 -> 0.6 | G3: =$P$3 -> 0.8 | K3: 1.2 | L3: 1.2 | M3: 1.8 | N3: 1 | O3: 0.6 | P3: 0.8
A4: Marek | B4: =VLOOKUP(Model!D3,Results!$K$8:$L$18,2,1) -> 9 | C4: =VLOOKUP(Model!E3,Results!$N$8:$O$18,2,1) -> 10 | D4: =VLOOKUP(Model!G3,Results!$Q$8:$R$18,2,1) -> 9 | E4: =VLOOKUP(Model!I3,Results!$T$8:$U$18,2,1) -> 9 | G4: 7 | H4: =SUMPRODUCT(B4:G4,$B$3:$G$3)/SUM($B$3:$G$3) -> 8.1212121
A5: Gracjan | B5: =VLOOKUP(Model!D20,Results!$K$8:$L$18,2,1) -> 1 | C5: =VLOOKUP(Model!E20,Results!$N$8:$O$18,2,1) -> 4 | D5: =VLOOKUP(Model!G20,Results!$Q$8:$R$18,2,1) -> 1 | E5: =VLOOKUP(Model!I20,Results!$T$8:$U$18,2,1) -> 10 | G5: 7 | H5: =SUMPRODUCT(B5:G5,$B$3:$G$3)/SUM($B$3:$G$3) -> 3.5454545
A6: Tomek | B6: =VLOOKUP(Model!D86,Results!$K$8:$L$18,2,1) -> 1 | C6: =VLOOKUP(Model!E86,Results!$N$8:$O$18,2,1) -> 1 | D6: =VLOOKUP(Model!G86,Results!$Q$8:$R$18,2,1) -> 1 | E6: =VLOOKUP(Model!I86,Results!$T$8:$U$18,2,1) -> 1 | G6: 7 | H6: =SUMPRODUCT(B6:G6,$B$3:$G$3)/SUM($B$3:$G$3) -> 1.6363636
A7: Paweł | B7: =VLOOKUP(Model!D53,Results!$K$8:$L$18,2,1) -> 1 | C7: =VLOOKUP(Model!E53,Results!$N$8:$O$18,2,1) -> 8 | D7: =VLOOKUP(Model!G53,Results!$Q$8:$R$18,2,1) -> 1 | E7: =VLOOKUP(Model!I53,Results!$T$8:$U$18,2,1) -> 7 | G7: 7 | H7: =SUMPRODUCT(B7:G7,$B$3:$G$3)/SUM($B$3:$G$3) -> 3.8181818 | K7: Points range
A8: Piotr | B8: =VLOOKUP(Model!D119,Results!$K$8:$L$18,2,1) -> 7 | C8: =VLOOKUP(Model!E119,Results!$N$8:$O$18,2,1) -> 4 | D8: =VLOOKUP(Model!G119,Results!$Q$8:$R$18,2,1) -> 6 | E8: =VLOOKUP(Model!I119,Results!$T$8:$U$18,2,1) -> 10 | G8: 7 | H8: =SUMPRODUCT(B8:G8,$B$3:$G$3)/SUM($B$3:$G$3) -> 6 | K8: Completed scope | N8: Scope vs Team (h) | Q8: Fokus rate | T8: Capacity | W8: Timeout of the task | Z8: Team's NPS
K9: 0 | L9: 1 | N9: 0 | O9: 1 | Q9: 0 | R9: 1 | T9: 0 | U9: 1 | W9: 0.9 | X9: 1 | Z9: 1 | AA9: 1
A10: Sprint 23 | K10: 0.2 | L10: 2 | N10: 0.3 | O10: 2 | Q10: 0.2 | R10: 2 | T10: 0.2 | U10: 2 | W10: 0.7 | X10: 2 | Z10: 2 | AA10: 2
B11: Completed scope | C11: Scope vs Team (h) | D11: Fokus rate | E11: Capacity | F11: Timeout of the task | G11: Team's NPS | H11: Score | K11: 0.3 | L11: 3 | N11: 0.4 | O11: 3 | Q11: 0.3 | R11: 3 | T11: 0.3 | U11: 3 | W11: 0.5 | X11: 3 | Z11: 3 | AA11: 3
A12: Waga | B12: =$K$3 -> 1.2 | C12: =$L$3 -> 1.2 | D12: =$M$3 -> 1.8 | E12: =$N$3 -> 1 | F12: =$O$3 -> 0.6 | G12: =$P$3 -> 0.8 | K12: 0.4 | L12: 4 | N12: 0.5 | O12: 4 | Q12: 0.4 | R12: 4 | T12: 0.4 | U12: 4 | W12: 0.4 | X12: 4 | Z12: 4 | AA12: 4
A13: Marek | B13: =VLOOKUP(Model!D4,Results!$K$8:$L$18,2,1) -> 7 | C13: =VLOOKUP(Model!E4,Results!$N$8:$O$18,2,1) -> 6 | D13: =VLOOKUP(Model!G4,Results!$Q$8:$R$18,2,1) -> 2 | E13: =VLOOKUP(Model!I4,Results!$T$8:$U$18,2,1) -> 8 | G13: 7 | H13: =SUMPRODUCT(B13:G13,$B$3:$G$3)/SUM($B$3:$G$3) -> 4.969697 | K13: 0.5 | L13: 5 | N13: 0.6 | O13: 5 | Q13: 0.5 | R13: 5 | T13: 0.5 | U13: 5 | W13: 0.3 | X13: 5 | Z13: 5 | AA13: 5
A14: Gracjan | B14: =VLOOKUP(Model!D21,Results!$K$8:$L$18,2,1) -> 1 | C14: =VLOOKUP(Model!E21,Results!$N$8:$O$18,2,1) -> 9 | D14: =VLOOKUP(Model!G21,Results!$Q$8:$R$18,2,1) -> 1 | E14: =VLOOKUP(Model!I21,Results!$T$8:$U$18,2,1) -> 10 | G14: 7 | H14: =SUMPRODUCT(B14:G14,$B$3:$G$3)/SUM($B$3:$G$3) -> 4.4545455 | K14: 0.6 | L14: 6 | N14: 0.7 | O14: 6 | Q14: 0.6 | R14: 6 | T14: 0.6 | U14: 6 | W14: 0.2 | X14: 6 | Z14: 6 | AA14: 6
A15: Tomek | B15: =VLOOKUP(Model!D87,Results!$K$8:$L$18,2,1) -> 1 | C15: =VLOOKUP(Model!E87,Results!$N$8:$O$18,2,1) -> 1 | D15: =VLOOKUP(Model!G87,Results!$Q$8:$R$18,2,1) -> 1 | E15: =VLOOKUP(Model!I87,Results!$T$8:$U$18,2,1) -> 1 | G15: 7 | H15: =SUMPRODUCT(B15:G15,$B$3:$G$3)/SUM($B$3:$G$3) -> 1.6363636 | K15: 0.7 | L15: 7 | N15: 0.8 | O15: 7 | Q15: 0.7 | R15: 7 | T15: 0.7 | U15: 7 | W15: 0.15 | X15: 7 | Z15: 7 | AA15: 7
A16: Paweł | B16: =VLOOKUP(Model!D54,Results!$K$8:$L$18,2,1) -> 1 | C16: =VLOOKUP(Model!E54,Results!$N$8:$O$18,2,1) -> 10 | D16: =VLOOKUP(Model!G54,Results!$Q$8:$R$18,2,1) -> 1 | E16: =VLOOKUP(Model!I54,Results!$T$8:$U$18,2,1) -> 7 | G16: 7 | H16: =SUMPRODUCT(B16:G16,$B$3:$G$3)/SUM($B$3:$G$3) -> 4.1818182 | K16: 0.8 | L16: 8 | N16: 0.9 | O16: 8 | Q16: 0.8 | R16: 8 | T16: 0.8 | U16: 8 | W16: 0.07 | X16: 8 | Z16: 8 | AA16: 8
A17: Piotr | B17: =VLOOKUP(Model!D120,Results!$K$8:$L$18,2,1) -> 6 | C17: =VLOOKUP(Model!E120,Results!$N$8:$O$18,2,1) -> 5 | D17: =VLOOKUP(Model!G120,Results!$Q$8:$R$18,2,1) -> 5 | E17: =VLOOKUP(Model!I120,Results!$T$8:$U$18,2,1) -> 8 | G17: 7 | H17: =SUMPRODUCT(B17:G17,$B$3:$G$3)/SUM($B$3:$G$3) -> 5.4242424 | K17: 0.9 | L17: 9 | N17: 1 | O17: 9 | Q17: 0.9 | R17: 9 | T17: 0.9 | U17: 9 | W17: 0 | X17: 9 | Z17: 9 | AA17: 9
K18: 1 | L18: 10 | N18: 1.2 | O18: 10 | Q18: 1 | R18: 10 | T18: 1 | U18: 10 | W18: -0.1 | X18: 10 | Z18: 10 | AA18: 10
A19: Sprint 24
B20: Completed scope | C20: Scope vs Team (h) | D20: Fokus rate | E20: Capacity | F20: Timeout of the task | G20: Team's NPS | H20: Score
A21: Waga | B21: =$K$3 -> 1.2 | C21: =$L$3 -> 1.2 | D21: =$M$3 -> 1.8 | E21: =$N$3 -> 1 | F21: =$O$3 -> 0.6 | G21: =$P$3 -> 0.8
A22: Marek | B22: =VLOOKUP(Model!D5,Results!$K$8:$L$18,2,1) -> 5 | C22: =VLOOKUP(Model!E5,Results!$N$8:$O$18,2,1) -> 8 | D22: =VLOOKUP(Model!G5,Results!$Q$8:$R$18,2,1) -> 6 | E22: =VLOOKUP(Model!I5,Results!$T$8:$U$18,2,1) -> 8 | G22: 7 | H22: =SUMPRODUCT(B22:G22,$B$3:$G$3)/SUM($B$3:$G$3) -> 6.0606061
A23: Gracjan | B23: =VLOOKUP(Model!D22,Results!$K$8:$L$18,2,1) -> 1 | C23: =VLOOKUP(Model!E22,Results!$N$8:$O$18,2,1) -> 10 | D23: =VLOOKUP(Model!G22,Results!$Q$8:$R$18,2,1) -> 1 | E23: =VLOOKUP(Model!I22,Results!$T$8:$U$18,2,1) -> 8 | G23: 7 | H23: =SUMPRODUCT(B23:G23,$B$3:$G$3)/SUM($B$3:$G$3) -> 4.3333333
A24: Tomek | B24: =VLOOKUP(Model!D88,Results!$K$8:$L$18,2,1) -> 1 | C24: =VLOOKUP(Model!E88,Results!$N$8:$O$18,2,1) -> 1 | D24: =VLOOKUP(Model!G88,Results!$Q$8:$R$18,2,1) -> 1 | E24: =VLOOKUP(Model!I88,Results!$T$8:$U$18,2,1) -> 1 | G24: 7 | H24: =SUMPRODUCT(B24:G24,$B$3:$G$3)/SUM($B$3:$G$3) -> 1.6363636
A25: Paweł | B25: =VLOOKUP(Model!D55,Results!$K$8:$L$18,2,1) -> 1 | C25: =VLOOKUP(Model!E55,Results!$N$8:$O$18,2,1) -> 6 | D25: =VLOOKUP(Model!G55,Results!$Q$8:$R$18,2,1) -> 1 | E25: =VLOOKUP(Model!I55,Results!$T$8:$U$18,2,1) -> 6 | G25: 7 | H25: =SUMPRODUCT(B25:G25,$B$3:$G$3)/SUM($B$3:$G$3) -> 3.3030303
A26: Piotr | B26: =VLOOKUP(Model!D121,Results!$K$8:$L$18,2,1) -> 10 | C26: =VLOOKUP(Model!E121,Results!$N$8:$O$18,2,1) -> 5 | D26: =VLOOKUP(Model!G121,Results!$Q$8:$R$18,2,1) -> 10 | E26: =VLOOKUP(Model!I121,Results!$T$8:$U$18,2,1) -> 7 | G26: 7 | H26: =SUMPRODUCT(B26:G26,$B$3:$G$3)/SUM($B$3:$G$3) -> 7.3636364
A28: Sprint 25
B29: Completed scope | C29: Scope vs Team (h) | D29: Fokus rate | E29: Capacity | F29: Timeout of the task | G29: Team's NPS | H29: Score
A30: Waga | B30: =$K$3 -> 1.2 | C30: =$L$3 -> 1.2 | D30: =$M$3 -> 1.8 | E30: =$N$3 -> 1 | F30: =$O$3 -> 0.6 | G30: =$P$3 -> 0.8
A31: Marek | B31: =VLOOKUP(Model!D6,Results!$K$8:$L$18,2,1) -> 5 | C31: =VLOOKUP(Model!E6,Results!$N$8:$O$18,2,1) -> 10 | D31: =VLOOKUP(Model!G6,Results!$Q$8:$R$18,2,1) -> 7 | E31: =VLOOKUP(Model!I6,Results!$T$8:$U$18,2,1) -> 7 | G31: 7 | H31: =SUMPRODUCT(B31:G31,$B$3:$G$3)/SUM($B$3:$G$3) -> 6.5454545
A32: Gracjan | B32: =VLOOKUP(Model!D23,Results!$K$8:$L$18,2,1) -> 1 | C32: =VLOOKUP(Model!E23,Results!$N$8:$O$18,2,1) -> 10 | D32: =VLOOKUP(Model!G23,Results!$Q$8:$R$18,2,1) -> 1 | E32: =VLOOKUP(Model!I23,Results!$T$8:$U$18,2,1) -> 8 | G32: 7 | H32: =SUMPRODUCT(B32:G32,$B$3:$G$3)/SUM($B$3:$G$3) -> 4.3333333
A33: Tomek | B33: =VLOOKUP(Model!D89,Results!$K$8:$L$18,2,1) -> 1 | C33: =VLOOKUP(Model!E89,Results!$N$8:$O$18,2,1) -> 1 | D33: =VLOOKUP(Model!G89,Results!$Q$8:$R$18,2,1) -> 1 | E33: =VLOOKUP(Model!I89,Results!$T$8:$U$18,2,1) -> 1 | G33: 7 | H33: =SUMPRODUCT(B33:G33,$B$3:$G$3)/SUM($B$3:$G$3) -> 1.6363636
A34: Paweł | B34: =VLOOKUP(Model!D56,Results!$K$8:$L$18,2,1) -> 1 | C34: =VLOOKUP(Model!E56,Results!$N$8:$O$18,2,1) -> 1 | D34: =VLOOKUP(Model!G56,Results!$Q$8:$R$18,2,1) -> 1 | E34: =VLOOKUP(Model!I56,Results!$T$8:$U$18,2,1) -> 9 | G34: 7 | H34: =SUMPRODUCT(B34:G34,$B$3:$G$3)/SUM($B$3:$G$3) -> 2.8484848
A35: Piotr | B35: =VLOOKUP(Model!D122,Results!$K$8:$L$18,2,1) -> 2 | C35: =VLOOKUP(Model!E122,Results!$N$8:$O$18,2,1) -> 1 | D35: =VLOOKUP(Model!G122,Results!$Q$8:$R$18,2,1) -> 5 | E35: =VLOOKUP(Model!I122,Results!$T$8:$U$18,2,1) -> 3 | G35: 7 | H35: =SUMPRODUCT(B35:G35,$B$3:$G$3)/SUM($B$3:$G$3) -> 3.2121212
A37: Sprint 26
B38: Completed scope | C38: Scope vs Team (h) | D38: Fokus rate | E38: Capacity | F38: Timeout of the task | G38: Team's NPS | H38: Score
A39: Waga | B39: =$K$3 -> 1.2 | C39: =$L$3 -> 1.2 | D39: =$M$3 -> 1.8 | E39: =$N$3 -> 1 | F39: =$O$3 -> 0.6 | G39: =$P$3 -> 0.8
A40: Marek | B40: =VLOOKUP(Model!D7,Results!$K$8:$L$18,2,1) -> 8 | C40: =VLOOKUP(Model!E7,Results!$N$8:$O$18,2,1) -> 8 | D40: =VLOOKUP(Model!G7,Results!$Q$8:$R$18,2,1) -> 7 | E40: =VLOOKUP(Model!I7,Results!$T$8:$U$18,2,1) -> 9 | G40: 7 | H40: =SUMPRODUCT(B40:G40,$B$3:$G$3)/SUM($B$3:$G$3) -> 7.030303
A41: Gracjan | B41: =VLOOKUP(Model!D24,Results!$K$8:$L$18,2,1) -> 1 | C41: =VLOOKUP(Model!E24,Results!$N$8:$O$18,2,1) -> 9 | D41: =VLOOKUP(Model!G24,Results!$Q$8:$R$18,2,1) -> 1 | E41: =VLOOKUP(Model!I24,Results!$T$8:$U$18,2,1) -> 10 | G41: 7 | H41: =SUMPRODUCT(B41:G41,$B$3:$G$3)/SUM($B$3:$G$3) -> 4.4545455
A42: Tomek | B42: =VLOOKUP(Model!D90,Results!$K$8:$L$18,2,1) -> 1 | C42: =VLOOKUP(Model!E90,Results!$N$8:$O$18,2,1) -> 1 | D42: =VLOOKUP(Model!G90,Results!$Q$8:$R$18,2,1) -> 1 | E42: =VLOOKUP(Model!I90,Results!$T$8:$U$18,2,1) -> 1 | G42: 7 | H42: =SUMPRODUCT(B42:G42,$B$3:$G$3)/SUM($B$3:$G$3) -> 1.6363636
...

Sheet Model
A1: Marek
A2: Sprint | B2: Completed | C2: Scope | D2: % Copleted | E2: Scope vs Team H | F2: Worked Hours | G2: Focus Rate | H2: Capacity | I2: % Capacity
A3: 22 (08.11-21.11) | B3: 46.75 | C3: 51.75 | D3: =B3/C3 -> 0.90338164 | E3: =B3/B179 -> 1.464752 | F3: 47.5 | G3: =B3/F3 -> 0.98421053 | H3: 50 | I3: =F3/H3 -> 0.95
A4: 23 (22.11-05.12) | B4: 12.67 | C4: 17.67 | D4: =B4/C4 -> 0.71703452 | E4: =B4/B180 -> 0.72510492 | F4: 50.5 | G4: =B4/F4 -> 0.25089109 | H4: 56.5 | I4: =F4/H4 -> 0.89380531
A5: 24 (06.12-19.12) | B5: 32 | C5: 58.75 | D5: =B5/C5 -> 0.54468085 | E5: =B5/B181 -> 0.92236741 | F5: 46 | G5: =B5/F5 -> 0.69565217 | H5: 56.5 | I5: =F5/H5 -> 0.81415929
A6: 25 (20.12-02.01) | B6: 30.5 | C6: 51.75 | D6: =B6/C6 -> 0.58937198 | E6: =B6/B182 -> 1.5822238 | F6: 41.75 | G6: =B6/F6 -> 0.73053892 | H6: 53.5 | I6: =F6/H6 -> 0.78037383
A7: 26 (03.01-16.01) | B7: 35 | C7: 42.5 | D7: =B7/C7 -> 0.82352941 | E7: =B7/B183 -> 0.95890411 | F7: 48.75 | G7: =B7/F7 -> 0.71794872 | H7: 53.5 | I7: =F7/H7 -> 0.91121495
A8: 27 (17.01-30.01) | B8: 59.35 | C8: 67.35 | D8: =B8/C8 -> 0.88121752 | E8: =B8/B184 -> 1.1789049 | F8: 52 | G8: =B8/F8 -> 1.1413462 | H8: 51.5 | I8: =F8/H8 -> 1.0097087
A9: 28 (31.01-13.02) | B9: 68.75 | C9: 67.75 | D9: =B9/C9 -> 1.0147601 | E9: =B9/B185 -> 1.2884183 | F9: 54 | G9: =B9/F9 -> 1.2731481 | H9: 55 | I9: =F9/H9 -> 0.98181818
A10: 29 (14.02-27.02) | B10: 41.17 | C10: 46.17 | D10: =B10/C10 -> 0.89170457 | E10: =B10/B186 -> 1.2118328 | F10: 62 | G10: =B10/F10 -> 0.66403226 | H10: 52 | I10: =F10/H10 -> 1.1923077
A11: 30 (28.02-13.03) | B11: 41 | C11: 37 | D11: =B11/C11 -> 1.1081081 | E11: =B11/B187 -> 0.84536082 | F11: 57.25 | G11: =B11/F11 -> 0.71615721 | H11: 55 | I11: =F11/H11 -> 1.0409091
A12: 31 (14.03-27.03) | B12: 56 | C12: 67 | D12: =B12/C12 -> 0.8358209 | E12: =B12/$B$188 -> 1.0434135 | F12: 63.5 | G12: =B12/F12 -> 0.88188976 | H12: 55 | I12: =F12/H12 -> 1.1545455
A13: =Sheet2!G3 -> 33 (06.06 - 19.06) | B13: 58.5 | C13: 57.5 | D13: =B13/C13 -> 1.0173913 | E13: =B13/$B$189 -> 1.6363636 | F13: 57.5 | G13: =B13/F13 -> 1.0173913 | H13: 42.4 | I13: =F13/H13 -> 1.3561321
A18: Gracjan | B18: Gracjan
A19: Sprint | B19: Completed | C19: Scope | D19: % Copleted | E19: Scope vs Team H | F19: Worked Hours | G19: Fokus Rate | H19: Capacity | I19: % Capacity
A20: 22 (08.11-21.11) | B20: 18.5 | C20: 39.17 | E20: =B20/B179 -> 0.57963446 | F20: 39 | H20: 33.5 | I20: =F20/H20 -> 1.1641791
A21: 23 (22.11-05.12) | B21: 17.75 | C21: 45.75 | E21: =B21/B180 -> 1.0158337 | F21: 58.5 | H21: 56.5 | I21: =F21/H21 -> 1.0353982
A22: 24 (06.12-19.12) | B22: 44.33 | C22: 57.33 | E22: =B22/B181 -> 1.2777671 | F22: 48.5 | H22: 56.5 | I22: =F22/H22 -> 0.85840708
A23: 25 (20.12-03.01) | B23: 23.33 | C23: 39.67 | E23: =B23/B182 -> 1.2102715 | F23: 46.25 | H23: 53.5 | I23: =F23/H23 -> 0.86448598
A24: 26 (03.01-16.01) | B24: 43.5 | C24: 59.5 | E24: =B24/B183 -> 1.1917808 | F24: 40.25 | H24: 38 | I24: =F24/H24 -> 1.0592105
A25: 27 (17.01-30.01) | B25: 45 | C25: 60 | E25: =B25/B184 -> 0.89386215 | F25: 41.25 | H25: 38 | I25: =F25/H25 -> 1.0855263
A26: 28 (31.01-13.02) | B26: 53.58 | C26: 57.58 | E26: =B26/$B185 -> 1.0041229 | F26: 48.25 | H26: 39.5 | I26: =F26/H26 -> 1.221519
A27: 29 (14.02-27.02) | B27: 28.5 | C27: 46 | E27: =B27/$B186 -> 0.83889325 | F27: 46.25 | H27: 39.5 | I27: =F27/H27 -> 1.1708861
A28: 30 (28.02-13.03) | B28: 42.5 | C28: 35.5 | E28: =B28/$B187 -> 0.87628866 | F28: 45.5 | H28: 39.5 | I28: =F28/H28 -> 1.1518987
A29: 31 (14.03-27.03) | B29: 53.67 | C29: 65.67 | E29: =B29/$B188 -> 1 | F29: 40.75 | H29: 39.5 | I29: =F29/H29 -> 1.0316456
A30: =Sheet2!G3 -> 33 (06.06 - 19.06) | B30: 38.25 | C30: 43 | E30: =B30/$B189 -> 1.0699301 | F30: 34 | H30: 31.9 | I30: =F30/H30 -> 1.0658307
A31: =Sheet2!G4 -> 34 (20.06 - 03.07) | B31: 39 | C31: 57 | D31: =B31/C31 -> 0.68421053 | E31: =B31/$B190 -> 0.98734177 | F31: =68-9.5-3 -> 55.5 | G31: =B31/F31 -> 0.7027027 | H31: 50.5 | I31: =F31/H31 -> 1.0990099
A32: =Sheet2!G5 -> 35 (04.07 - 17.07) | B32: 47 | C32: 54 | D32: =B32/C32 -> 0.87037037 | E32: =B32/$B191 -> 0.96575342 | F32: 52.5 | G32: =B32/F32 -> 0.8952381 | H32: 51 | I32: =F32/H32 -> 1.0294118
A33: =Sheet2!G6 -> 36 (18.07 - 31.07) | B33: 40.5 | C33: 45 | D33: =B33/C33 -> 0.9 | E33: =B33/$B192 -> 0.86476868 | F33: 50.75 | G33: =B33/F33 -> 0.79802956 | H33: 56 | I33: =F33/H33 -> 0.90625
A34: =Sheet2!G7 -> 37 (01.08 - 14.08) | B34: 40.5 | C34: 64.5 | D34: =B34/C34 -> 0.62790698 | E34: =B34/$B193 -> 0.93822394 | F34: 47.25 | G34: =B34/F34 -> 0.85714286 | H34: 48 | I34: =F34/H34 -> 0.984375
A35: =Sheet2!G8 -> 38 (15.08 - 28.08) | B35: 48 | C35: 69 | D35: =B35/C35 -> 0.69565217 | E35: =B35/$B194 -> 0.92307692 | F35: 42 | G35: =B35/F35 -> 1.1428571 | H35: 36 | I35: =F35/H35 -> 1.1666667
A36: =Sheet2!G9 -> 39 (29.08 - 11.09) | B36: 51 | C36: 41 | D36: =B36/C36 -> 1.2439024 | E36: =B36/$B195 -> 1.0712035 | F36: 48.75 | G36: =B36/F36 -> 1.0461538 | H36: 39 | I36: =F36/H36 -> 1.25
A37: =Sheet2!G10 -> 40 (12.09 - 25.09) | B37: 46 | C37: 46 | D37: =B37/C37 -> 1 | E37: =B37/$B196 -> 1.0615385 | F37: 46.75 | G37: =B37/F37 -> 0.98395722 | H37: 41 | I37: =F37/H37 -> 1.1402439
A38: =Sheet2!G11 -> 41 (26.09 - 09.10) | B38: 64 | C38: 42 | D38: =B38/C38 -> 1.5238095 | E38: =B38/$B197 -> 1.0666667 | F38: 55.25 | G38: =B38/F38 -> 1.158371 | H38: 55.5 | I38: =F38/H38 -> 0.9954955
A39: =Sheet2!G12 -> 42 (10.10 - 23.10) | B39: 45 | C39: 43 | D39: =B39/C39 -> 1.0465116 | E39: =B39/$B198 -> 0.59734513 | F39: 55.5 | G39: =B39/F39 -> 0.81081081 | H39: 42 | I39: =F39/H39 -> 1.3214286
A40: =Sheet2!G13 -> 43 (24.10 - 06.11) | B40: 71 | C40: 60 | D40: =B40/C40 -> 1.1833333 | E40: =B40/$B199 -> 1.2792793 | F40: 50.75 | G40: =B40/F40 -> 1.3990148 | H40: 46 | I40: =F40/H40 -> 1.1032609
A41: =Sheet2!G14 -> 44 (07.11 - 20.11) | B41: 52 | C41: 60 | D41: =B41/C41 -> 0.86666667 | E41: =B41/$B200 -> 0.77227723 | F41: 55.5 | G41: =B41/F41 -> 0.93693694 | H41: 49 | I41: =F41/H41 -> 1.1326531
A42: =Sheet2!G15 -> 45 (21.11 - 04.12) | B42: 89 | C42: 79 | D42: =B42/C42 -> 1.1265823 | E42: =B42/$B201 -> 1.2418605 | F42: 67.75 | G42: =B42/F42 -> 1.3136531 | H42: 54 | I42: =F42/H42 -> 1.2546296
A43: =Sheet2!G16 -> 46 (05.12 - 18.12) | B43: 64 | C43: 39 | D43: =B43/C43 -> 1.6410256 | E43: =B43/$B202 -> 0.84955752 | F43: 56.75 | G43: =B43/F43 -> 1.1277533 | H43: 48 | I43: =F43/H43 -> 1.1822917
A44: =Sheet2!G17 -> 47 (19.12 - 01.01) | B44: 36 | C44: 39 | D44: =B44/C44 -> 0.92307692
...

Sheet Model Kar - Darft
K1: Zakres punktowe | L1: Poziom rabatu / dodatku
B2: Sprint 25 | C2: Sprint 26 | D2: Sprint 27 | E2: 33 | F2: AVG - Sprints | G2: Kara/Wzrost | H2: Liczba rabatowanych h | I2: Kwota | K2: 0 | L2: -1 | N2: -1
A3: Marek | B3: =Results!B$242 -> 6.5454545 | C3: =Results!B243 -> 7.030303 | D3: =Results!B244 -> 8.1818182 | E3: =_xlfn.XLOOKUP(A3,Results!$A$238:$F$238,Results!$A$249:$F$249) -> 8.7272727 | F3: =AVERAGE(B3:E3) -> 7.6212121 | G3: =VLOOKUP(F3,$K$2:$L$12,2,1) -> 0 | H3: =AVERAGE(Model!F13,G8,G6)*G3 -> 0 | I3: =H3*245 -> 0 | K3: 1 | L3: -0.5 | N3: -0.5
A4: Gracjan | B4: =Results!C$242 -> 4.3333333 | C4: =Results!C243 -> 4.4545455 | D4: =Results!C244 -> 4.0909091 | E4: =_xlfn.XLOOKUP(A4,Results!$A$238:$F$238,Results!$A$249:$F$249) -> 4.6363636 | F4: =AVERAGE(B4:E4) -> 4.3787879 | G4: =VLOOKUP(F4,$K$2:$L$12,2,1) -> -0.15 | H4: =AVERAGE(Model!F30,G20,G18)*G4 -> -5.1 | I4: =H4*245 -> -1249.5 | K4: 2 | L4: -0.3 | N4: -0.3
A5: Tomek | B5: =Results!D$242 -> 0 | C5: =Results!D243 -> 0 | D5: =Results!D244 -> 0 | E5: 0 | F5: =AVERAGE(B5:E5) -> 0 | G5: =VLOOKUP(F5,$K$2:$L$12,2,1) -> -1 | H5: 0 | I5: 0 | J5: =160*245 -> 39200 | K5: 3 | L5: -0.2 | N5: -0.2
A6: Paweł | B6: =Results!E$242 -> 2.8484848 | C6: =Results!E243 -> 3.6363636 | D6: =Results!E244 -> 4.1212121 | E6: =_xlfn.XLOOKUP(A6,Results!$A$238:$F$238,Results!$A$249:$F$249) -> 2.5757576 | F6: =AVERAGE(B6:E6) -> 3.2954545 | G6: =VLOOKUP(F6,$K$2:$L$12,2,1) -> -0.2 | H6: =AVERAGE(Model!F63,G31,G32)*G6 -> -5.85 | I6: =H6*245 -> -1433.25 | K6: 4 | L6: -0.15 | N6: -0.1
A7: Piotr | B7: =Results!F$242 -> 3.2121212 | C7: =Results!F243 -> 3.4545455 | D7: =Results!F244 -> 7.8181818 | E7: =_xlfn.XLOOKUP(A7,Results!$A$238:$F$238,Results!$A$249:$F$249) -> 2.9090909 | F7: =AVERAGE(B7:E7) -> 4.3484848 | G7: =VLOOKUP(F7,$K$2:$L$12,2,1) -> -0.15 | H7: =AVERAGE(Model!F129,G32,G33)*G7 -> -2.238 | I7: =H7*245 -> -548.31 | K7: 5 | L7: -0.1 | N7: -0.05
A8: Hania | E8: =_xlfn.XLOOKUP(A8,Results!$A$238:$F$238,Results!$A$249:$F$249) -> 7.6363636 | F8: =AVERAGE(B8:E8) -> 7.6363636 | G8: =VLOOKUP(F8,$K$2:$L$12,2,1) -> 0 | H8: =AVERAGE(Model!F96,G33,G34)*G8 -> 0 | I8: =H8*245 -> 0 | K8: 6 | L8: -0.05 | N8: 0
H9: Suma | I9: =SUM(I3:I8) -> -3231.06 | K9: 7 | L9: 0 | N9: 0
K10: 8 | L10: 0 | N10: 0
K11: 9 | L11: 0.05 | N11: 0.05
I12: =I5*3 -> 0 | K12: 10 | L12: 0.15 | N12: 0.15

Sheet Sheet2
C2: SPRINT | D2: START | E2: STOP
C3: 33 | D3: 45083 | E3: 45096 | G3: 33 (06.06 - 19.06)
C4: 34 | D4: 45097 | E4: 45110 | F4: 20.06 - 03.07 | G4: 34 (20.06 - 03.07)
C5: 35 | D5: 45111 | E5: 45124 | F5: 04.07 - 17.07 | G5: 35 (04.07 - 17.07)
C6: 36 | D6: 45125 | E6: 45138 | F6: 18.07 - 31.07 | G6: 36 (18.07 - 31.07)
C7: 37 | D7: 45139 | E7: 45152 | F7: 01.08 - 14.08 | G7: 37 (01.08 - 14.08)
C8: 38 | D8: 45153 | E8: 45166 | F8: 15.08 - 28.08 | G8: 38 (15.08 - 28.08)
C9: 39 | D9: 45167 | E9: 45180 | F9: 29.08 - 11.09 | G9: 39 (29.08 - 11.09)
C10: 40 | D10: 45181 | E10: 45194 | F10: 12.09 - 25.09 | G10: 40 (12.09 - 25.09)
C11: 41 | D11: 45195 | E11: 45208 | F11: 26.09 - 09.10 | G11: 41 (26.09 - 09.10)
C12: 42 | D12: 45209 | E12: 45222 | F12: 10.10 - 23.10 | G12: 42 (10.10 - 23.10)
C13: 43 | D13: 45223 | E13: 45236 | F13: 24.10 - 06.11 | G13: 43 (24.10 - 06.11)
C14: 44 | D14: 45237 | E14: 45250 | F14: 07.11 - 20.11 | G14: 44 (07.11 - 20.11)
C15: 45 | D15: 45251 | E15: 45264 | F15: 21.11 - 04.12 | G15: 45 (21.11 - 04.12)
... C17: 47 | D17: 45279 | E17: 45292 | F17: 19.12 - 01.01 | G17: 47 (19.12 - 01.01)

Sheet archives

Sheet Sheet1MM
